<?xml version="1.0" encoding="utf-8"?>
<robot name="01_hand_r_fih_v20_asm">

	<material name="hand_color">
		<color rgba="0.792 0.820 0.933 1" />
	</material>

	<link name="fih_z_hand_r_base_link">
		<inertial>
			<origin xyz="0.024699 0.002853 0.001734" rpy="0 0 0" />
			<mass value="0.038686" />
			<inertia ixx="1.062968e-05" ixy="-3.748245e-06" ixz="-1.392614e-06" iyy="1.714280e-05" iyz="-2.573853e-07" izz="2.642744e-05" />
		</inertial>
		<visual>
			<geometry>
				<mesh filename="../meshes/FIH_HAND_R_ZHAOWEI/R_HAND_BASE.STL" />
			</geometry>
			<material name="hand_color" />
		</visual>
		<collision>
			<geometry>
				<mesh filename="../meshes/FIH_HAND_R_ZHAOWEI/R_HAND_BASE.STL" />
			</geometry>
		</collision>
	</link>

	<link name="L_T_J1">
		<inertial>
			<origin xyz="0.007145 -0.001439 0.004815" rpy="0 0 0" />
			<mass value="0.001791" />
			<inertia ixx="1.573251e-07" ixy="-7.117377e-09" ixz="4.372719e-09" iyy="1.398212e-07" iyz="-3.701533e-08" izz="5.541514e-08" />
		</inertial>
		<visual>
			<geometry>
				<mesh filename="../meshes/FIH_HAND_R_ZHAOWEI/L_T_J1.STL" />
			</geometry>
			<material name="hand_color" />
		</visual>
		<collision>
			<geometry>
				<mesh filename="../meshes/FIH_HAND_R_ZHAOWEI/L_T_J1.STL" />
			</geometry>
		</collision>
	</link>
	<joint name="T_J1" type="revolute">
		<origin xyz="-0.012827 0.032945 -0.011882" rpy="0 0 1.309" />
		<parent link="fih_z_hand_r_base_link" />
		<child link="L_T_J1" />
		<axis xyz="0 1 0" />
		<limit lower="0" upper="2.2835" effort="0" velocity="0" />
	</joint>

	<link name="L_T_J2">
		<inertial>
			<origin xyz="0.033861 0.000255 -0.005408" rpy="0 0 0" />
			<mass value="0.009615" />
			<inertia ixx="4.329191e-07" ixy="7.158225e-07" ixz="1.044962e-07" iyy="3.378217e-06" iyz="-4.819391e-08" izz="3.550903e-06" />
		</inertial>
		<visual>
			<geometry>
				<mesh filename="../meshes/FIH_HAND_R_ZHAOWEI/L_T_J2.STL" />
			</geometry>
			<material name="hand_color" />
		</visual>
		<collision>
			<geometry>
				<mesh filename="../meshes/FIH_HAND_R_ZHAOWEI/L_T_J2.STL" />
			</geometry>
		</collision>
	</link>
	<joint name="T_J2" type="revolute">
		<origin xyz="0.0097888 0.0051537 0.014364" rpy="-0.23678 0.26797 0" />
		<parent link="L_T_J1" />
		<child link="L_T_J2" />
		<axis xyz="0 0 1" />
		<limit lower="-1.3809" upper="0" effort="0" velocity="0" />
	</joint>

	<link name="L_T_J3">
		<inertial>
			<origin xyz="0.014122 0.001171 -0.000375" rpy="0 0 0" />
			<mass value="0.005264" />
			<inertia ixx="3.256736e-07" ixy="2.276884e-08" ixz="-9.251373e-08" iyy="6.447870e-07" iyz="-1.882080e-09" izz="6.874557e-07" />
		</inertial>
		<visual>
			<geometry>
				<mesh filename="../meshes/FIH_HAND_R_ZHAOWEI/L_T_J3.STL" />
			</geometry>
			<material name="hand_color" />
		</visual>
		<collision>
			<geometry>
				<mesh filename="../meshes/FIH_HAND_R_ZHAOWEI/L_T_J3.STL" />
			</geometry>
		</collision>
	</link>
	<joint name="T_J3" type="revolute">
		<origin xyz="0.06741 -0.0076576 -0.0085065" rpy="-0.61087 0 -0.33992" />
		<parent link="L_T_J2" />
		<child link="L_T_J3" />
		<axis xyz="0 1 0" />
		<limit lower="0" upper="1.0573" effort="0" velocity="0" />
	</joint>

	<link name="L_T_J4">
		<inertial>
			<origin xyz="0.012655 -0.000045 0.001432" rpy="0 0 0" />
			<mass value="0.005606" />
			<inertia ixx="2.516417e-07" ixy="-2.154044e-09" ixz="-6.616384e-08" iyy="3.073506e-07" iyz="-1.532852e-09" izz="3.591174e-07" />
		</inertial>
		<visual>
			<geometry>
				<mesh filename="../meshes/FIH_HAND_R_ZHAOWEI/L_T_J4.STL" />
			</geometry>
			<material name="hand_color" />
		</visual>
		<collision>
			<geometry>
				<mesh filename="../meshes/FIH_HAND_R_ZHAOWEI/L_T_J4.STL" />
			</geometry>
		</collision>
	</link>
	<joint name="T_J4" type="revolute">
		<origin xyz="0.0365 0 0.0029378" rpy="0 0 0" />
		<parent link="L_T_J3" />
		<child link="L_T_J4" />
		<axis xyz="0 1 0" />
		<limit lower="0" upper="0.7714" effort="0" velocity="0" />
	</joint>

	<link name="L_F1_J1">
		<inertial>
			<origin xyz="0.002490 -0.001196 -0.002215" rpy="0 0 0" />
			<mass value="0.000594" />
			<inertia ixx="1.235470e-08" ixy="5.142835e-10" ixz="1.253181e-09" iyy="1.259654e-08" iyz="-1.965720e-09" izz="7.479375e-09" />
		</inertial>
		<visual>
			<geometry>
				<mesh filename="../meshes/FIH_HAND_R_ZHAOWEI/L_F1_J1.STL" />
			</geometry>
			<material name="hand_color" />
		</visual>
		<collision>
			<geometry>
				<mesh filename="../meshes/FIH_HAND_R_ZHAOWEI/L_F1_J1.STL" />
			</geometry>
		</collision>
	</link>
	<joint name="F1_J1" type="revolute">
		<origin xyz="0.079768 0.039143 0.0041075" rpy="0 -0.2618 0.073258" />
		<parent link="fih_z_hand_r_base_link" />
		<child link="L_F1_J1" />
		<axis xyz="0 0 1" />
		<limit lower="-0.2618" upper="0.2618" effort="0" velocity="0" />
	</joint>

	<link name="L_F1_J2">
		<inertial>
			<origin xyz="0.013691 0.000867 0.000898" rpy="0 0 0" />
			<mass value="0.004158" />
			<inertia ixx="2.663598e-07" ixy="-1.964405e-09" ixz="-7.452387e-08" iyy="4.709684e-07" iyz="-3.794088e-09" izz="5.335600e-07" />
		</inertial>
		<visual>
			<geometry>
				<mesh filename="../meshes/FIH_HAND_R_ZHAOWEI/L_F1_J2.STL" />
			</geometry>
			<material name="hand_color" />
		</visual>
		<collision>
			<geometry>
				<mesh filename="../meshes/FIH_HAND_R_ZHAOWEI/L_F1_J2.STL" />
			</geometry>
		</collision>
	</link>
	<joint name="F1_J2" type="revolute">
		<origin xyz="0.003 -0.000825 -0.009075" rpy="0 0.2618 0" />
		<parent link="L_F1_J1" />
		<child link="L_F1_J2" />
		<axis xyz="0 1 0" />
		<limit lower="-0.3222" upper="1.4912" effort="0" velocity="0" />
	</joint>

	<link name="L_F1_J3">
		<inertial>
			<origin xyz="0.013726 -0.000171 -0.001798" rpy="0 0 0" />
			<mass value="0.004373" />
			<inertia ixx="2.552264e-07" ixy="5.181572e-09" ixz="9.373228e-10" iyy="4.841354e-07" iyz="6.949725e-10" izz="5.797885e-07" />
		</inertial>
		<visual>
			<geometry>
				<mesh filename="../meshes/FIH_HAND_R_ZHAOWEI/L_F1_J3.STL" />
			</geometry>
			<material name="hand_color" />
		</visual>
		<collision>
			<geometry>
				<mesh filename="../meshes/FIH_HAND_R_ZHAOWEI/L_F1_J3.STL" />
			</geometry>
		</collision>
	</link>
	<joint name="F1_J3" type="revolute">
		<origin xyz="0.033 0.000825 0.004" rpy="0 0 0" />
		<parent link="L_F1_J2" />
		<child link="L_F1_J3" />
		<axis xyz="0 1 0" />
		<limit lower="0" upper="1.2966" effort="0" velocity="0" />
	</joint>

	<link name="L_F1_J4">
		<inertial>
			<origin xyz="0.012816 -0.000022 -0.000164" rpy="0 0 0" />
			<mass value="0.005541" />
			<inertia ixx="2.356529e-07" ixy="-2.332143e-09" ixz="-5.046792e-08" iyy="3.073145e-07" iyz="-1.246694e-09" izz="3.730348e-07" />
		</inertial>
		<visual>
			<geometry>
				<mesh filename="../meshes/FIH_HAND_R_ZHAOWEI/L_F1_J4.STL" />
			</geometry>
			<material name="hand_color" />
		</visual>
		<collision>
			<geometry>
				<mesh filename="../meshes/FIH_HAND_R_ZHAOWEI/L_F1_J4.STL" />
			</geometry>
		</collision>
	</link>
	<joint name="F1_J4" type="revolute">
		<origin xyz="0.033 0 0" rpy="0 0 0" />
		<parent link="L_F1_J3" />
		<child link="L_F1_J4" />
		<axis xyz="0 1 0" />
		<limit lower="0" upper="1.1421" effort="0" velocity="0" />
	</joint>

	<link name="L_F2_J1">
		<inertial>
			<origin xyz="0.002979 -0.001196 -0.001495" rpy="0 0 0" />
			<mass value="0.000594" />
			<inertia ixx="1.140153e-08" ixy="1.005525e-09" ixz="2.304119e-09" iyy="1.259654e-08" iyz="-1.765635e-09" izz="8.432551e-09" />
		</inertial>
		<visual>
			<geometry>
				<mesh filename="../meshes/FIH_HAND_R_ZHAOWEI/L_F2_J1.STL" />
			</geometry>
			<material name="hand_color" />
		</visual>
		<collision>
			<geometry>
				<mesh filename="../meshes/FIH_HAND_R_ZHAOWEI/L_F2_J1.STL" />
			</geometry>
		</collision>
	</link>
	<joint name="F2_J1" type="revolute">
		<origin xyz="0.086755 0.017383 0.0041075" rpy="0 0 0.027471" />
		<parent link="fih_z_hand_r_base_link" />
		<child link="L_F2_J1" />
		<axis xyz="0 0 1" />
		<limit lower="-0.2618" upper="0.2618" effort="0" velocity="0" />
	</joint>

	<link name="L_F2_J2">
		<inertial>
			<origin xyz="0.013691 0.000867 0.000898" rpy="0 0 0" />
			<mass value="0.004158" />
			<inertia ixx="2.663598e-07" ixy="-1.964402e-09" ixz="-7.452387e-08" iyy="4.709684e-07" iyz="-3.794091e-09" izz="5.335600e-07" />
		</inertial>
		<visual>
			<geometry>
				<mesh filename="../meshes/FIH_HAND_R_ZHAOWEI/L_F2_J2.STL" />
			</geometry>
			<material name="hand_color" />
		</visual>
		<collision>
			<geometry>
				<mesh filename="../meshes/FIH_HAND_R_ZHAOWEI/L_F2_J2.STL" />
			</geometry>
		</collision>
	</link>
	<joint name="F2_J2" type="revolute">
		<origin xyz="0.0052466 -0.000825 -0.0079893" rpy="0 0 0" />
		<parent link="L_F2_J1" />
		<child link="L_F2_J2" />
		<axis xyz="0 1 0" />
		<limit lower="-0.3028" upper="1.5151" effort="0" velocity="0" />
	</joint>

	<link name="L_F2_J3">
		<inertial>
			<origin xyz="0.013751 -0.000201 -0.001812" rpy="0 0 0" />
			<mass value="0.004357" />
			<inertia ixx="2.551663e-07" ixy="5.181590e-09" ixz="9.373164e-10" iyy="4.841229e-07" iyz="6.948953e-10" izz="5.797284e-07" />
		</inertial>
		<visual>
			<geometry>
				<mesh filename="../meshes/FIH_HAND_R_ZHAOWEI/L_F2_J3.STL" />
			</geometry>
			<material name="hand_color" />
		</visual>
		<collision>
			<geometry>
				<mesh filename="../meshes/FIH_HAND_R_ZHAOWEI/L_F2_J3.STL" />
			</geometry>
		</collision>
	</link>
	<joint name="F2_J3" type="revolute">
		<origin xyz="0.033 0.000825 0.004" rpy="0 0 0" />
		<parent link="L_F2_J2" />
		<child link="L_F2_J3" />
		<axis xyz="0 1 0" />
		<limit lower="0" upper="1.2966" effort="0" velocity="0" />
	</joint>

	<link name="L_F2_J4">
		<inertial>
			<origin xyz="0.012816 -0.000022 -0.000164" rpy="0 0 0" />
			<mass value="0.005541" />
			<inertia ixx="2.356529e-07" ixy="-2.332073e-09" ixz="-5.046791e-08" iyy="3.073143e-07" iyz="-1.246742e-09" izz="3.730346e-07" />
		</inertial>
		<visual>
			<geometry>
				<mesh filename="../meshes/FIH_HAND_R_ZHAOWEI/L_F2_J4.STL" />
			</geometry>
			<material name="hand_color" />
		</visual>
		<collision>
			<geometry>
				<mesh filename="../meshes/FIH_HAND_R_ZHAOWEI/L_F2_J4.STL" />
			</geometry>
		</collision>
	</link>
	<joint name="F2_J4" type="revolute">
		<origin xyz="0.033 0 0" rpy="0 0 0" />
		<parent link="L_F2_J3" />
		<child link="L_F2_J4" />
		<axis xyz="0 1 0" />
		<limit lower="0" upper="1.1421" effort="0" velocity="0" />
	</joint>

	<link name="L_F3_J1">
		<inertial>
			<origin xyz="0.002490 -0.001196 -0.002215" rpy="0 0 0" />
			<mass value="0.000594" />
			<inertia ixx="1.235470e-08" ixy="5.142829e-10" ixz="1.253181e-09" iyy="1.259654e-08" iyz="-1.965722e-09" izz="7.479376e-09" />
		</inertial>
		<visual>
			<geometry>
				<mesh filename="../meshes/FIH_HAND_R_ZHAOWEI/L_F3_J1.STL" />
			</geometry>
			<material name="hand_color" />
		</visual>
		<collision>
			<geometry>
				<mesh filename="../meshes/FIH_HAND_R_ZHAOWEI/L_F3_J1.STL" />
			</geometry>
		</collision>
	</link>
	<joint name="F3_J1" type="revolute">
		<origin xyz="0.079755 -0.0043288 0.0041075" rpy="0 -0.2618 -0.027469" />
		<parent link="fih_z_hand_r_base_link" />
		<child link="L_F3_J1" />
		<axis xyz="0 0 1" />
		<limit lower="-0.2618" upper="0.2618" effort="0" velocity="0" />
	</joint>

	<link name="L_F3_J2">
		<inertial>
			<origin xyz="0.013691 0.000867 0.000898" rpy="0 0 0" />
			<mass value="0.004158" />
			<inertia ixx="2.663598e-07" ixy="-1.964398e-09" ixz="-7.452386e-08" iyy="4.709685e-07" iyz="-3.794094e-09" izz="5.335601e-07" />
		</inertial>
		<visual>
			<geometry>
				<mesh filename="../meshes/FIH_HAND_R_ZHAOWEI/L_F3_J2.STL" />
			</geometry>
			<material name="hand_color" />
		</visual>
		<collision>
			<geometry>
				<mesh filename="../meshes/FIH_HAND_R_ZHAOWEI/L_F3_J2.STL" />
			</geometry>
		</collision>
	</link>
	<joint name="F3_J2" type="revolute">
		<origin xyz="0.003 -0.000825 -0.009075" rpy="0 0.2618 0" />
		<parent link="L_F3_J1" />
		<child link="L_F3_J2" />
		<axis xyz="0 1 0" />
		<limit lower="-0.2820" upper="1.5423" effort="0" velocity="0" />
	</joint>

	<link name="L_F3_J3">
		<inertial>
			<origin xyz="0.013726 -0.000171 -0.001798" rpy="0 0 0" />
			<mass value="0.004373" />
			<inertia ixx="2.552264e-07" ixy="5.181545e-09" ixz="9.373220e-10" iyy="4.841356e-07" iyz="6.949806e-10" izz="5.797886e-07" />
		</inertial>
		<visual>
			<geometry>
				<mesh filename="../meshes/FIH_HAND_R_ZHAOWEI/L_F3_J3.STL" />
			</geometry>
			<material name="hand_color" />
		</visual>
		<collision>
			<geometry>
				<mesh filename="../meshes/FIH_HAND_R_ZHAOWEI/L_F3_J3.STL" />
			</geometry>
		</collision>
	</link>
	<joint name="F3_J3" type="revolute">
		<origin xyz="0.033 0.000825 0.004" rpy="0 0 0" />
		<parent link="L_F3_J2" />
		<child link="L_F3_J3" />
		<axis xyz="0 1 0" />
		<limit lower="0" upper="1.2966" effort="0" velocity="0" />
	</joint>

	<link name="L_F3_J4">
		<inertial>
			<origin xyz="0.012816 -0.000022 -0.000164" rpy="0 0 0" />
			<mass value="0.005541" />
			<inertia ixx="2.356528e-07" ixy="-2.332004e-09" ixz="-5.046791e-08" iyy="3.073141e-07" iyz="-1.246774e-09" izz="3.730344e-07" />
		</inertial>
		<visual>
			<geometry>
				<mesh filename="../meshes/FIH_HAND_R_ZHAOWEI/L_F3_J4.STL" />
			</geometry>
			<material name="hand_color" />
		</visual>
		<collision>
			<geometry>
				<mesh filename="../meshes/FIH_HAND_R_ZHAOWEI/L_F3_J4.STL" />
			</geometry>
		</collision>
	</link>
	<joint name="F3_J4" type="revolute">
		<origin xyz="0.033 0 0" rpy="0 0 0" />
		<parent link="L_F3_J3" />
		<child link="L_F3_J4" />
		<axis xyz="0 1 0" />
		<limit lower="0" upper="1.1421" effort="0" velocity="0" />
	</joint>

	<link name="L_F4_J1">
		<inertial>
			<origin xyz="0.002490 -0.001196 -0.002215" rpy="0 0 0" />
			<mass value="0.000594" />
			<inertia ixx="1.235470e-08" ixy="5.142829e-10" ixz="1.253181e-09" iyy="1.259654e-08" iyz="-1.965722e-09" izz="7.479375e-09" />
		</inertial>
		<visual>
			<geometry>
				<mesh filename="../meshes/FIH_HAND_R_ZHAOWEI/L_F4_J1.STL" />
			</geometry>
			<material name="hand_color" />
		</visual>
		<collision>
			<geometry>
				<mesh filename="../meshes/FIH_HAND_R_ZHAOWEI/L_F4_J1.STL" />
			</geometry>
		</collision>
	</link>
	<joint name="F4_J1" type="revolute">
		<origin xyz="0.069761 -0.026185 0.0041075" rpy="0 -0.2618 -0.054935" />
		<parent link="fih_z_hand_r_base_link" />
		<child link="L_F4_J1" />
		<axis xyz="0 0 1" />
		<limit lower="-0.2618" upper="0.2618" effort="0" velocity="0" />
	</joint>

	<link name="L_F4_J2">
		<inertial>
			<origin xyz="0.013691 0.000867 0.000898" rpy="0 0 0" />
			<mass value="0.004158" />
			<inertia ixx="2.663597e-07" ixy="-1.964396e-09" ixz="-7.452386e-08" iyy="4.709685e-07" iyz="-3.794094e-09" izz="5.335601e-07" />
		</inertial>
		<visual>
			<geometry>
				<mesh filename="../meshes/FIH_HAND_R_ZHAOWEI/L_F4_J2.STL" />
			</geometry>
			<material name="hand_color" />
		</visual>
		<collision>
			<geometry>
				<mesh filename="../meshes/FIH_HAND_R_ZHAOWEI/L_F4_J2.STL" />
			</geometry>
		</collision>
	</link>
	<joint name="F4_J2" type="revolute">
		<origin xyz="0.003 -0.000825 -0.009075" rpy="0 0.2618 0" />
		<parent link="L_F4_J1" />
		<child link="L_F4_J2" />
		<axis xyz="0 1 0" />
		<limit lower="-0.2608" upper="1.5722" effort="0" velocity="0" />
	</joint>

	<link name="L_F4_J3">
		<inertial>
			<origin xyz="0.013726 -0.000171 -0.001798" rpy="0 0 0" />
			<mass value="0.004373" />
			<inertia ixx="2.552264e-07" ixy="5.181534e-09" ixz="9.373218e-10" iyy="4.841356e-07" iyz="6.949833e-10" izz="5.797887e-07" />
		</inertial>
		<visual>
			<geometry>
				<mesh filename="../meshes/FIH_HAND_R_ZHAOWEI/L_F4_J3.STL" />
			</geometry>
			<material name="hand_color" />
		</visual>
		<collision>
			<geometry>
				<mesh filename="../meshes/FIH_HAND_R_ZHAOWEI/L_F4_J3.STL" />
			</geometry>
		</collision>
	</link>
	<joint name="F4_J3" type="revolute">
		<origin xyz="0.033 0.000825 0.004" rpy="0 0 0" />
		<parent link="L_F4_J2" />
		<child link="L_F4_J3" />
		<axis xyz="0 1 0" />
		<limit lower="0" upper="1.2966" effort="0" velocity="0" />
	</joint>

	<link name="L_F4_J4">
		<inertial>
			<origin xyz="0.012816 -0.000022 -0.000164" rpy="0 0 0" />
			<mass value="0.005541" />
			<inertia ixx="2.356528e-07" ixy="-2.332015e-09" ixz="-5.046791e-08" iyy="3.073142e-07" iyz="-1.246758e-09" izz="3.730345e-07" />
		</inertial>
		<visual>
			<geometry>
				<mesh filename="../meshes/FIH_HAND_R_ZHAOWEI/L_F4_J4.STL" />
			</geometry>
			<material name="hand_color" />
		</visual>
		<collision>
			<geometry>
				<mesh filename="../meshes/FIH_HAND_R_ZHAOWEI/L_F4_J4.STL" />
			</geometry>
		</collision>
	</link>
	<joint name="F4_J4" type="revolute">
		<origin xyz="0.033 0 0" rpy="0 0 0" />
		<parent link="L_F4_J3" />
		<child link="L_F4_J4" />
		<axis xyz="0 1 0" />
		<limit lower="0" upper="1.1421" effort="0" velocity="0" />
	</joint>

	<link name="wrist_center">
		<inertial>
			<origin xyz="0 0 0" rpy="0 0 0" />
			<mass value="0" />
			<inertia ixx="0" ixy="0" ixz="0" iyy="0" iyz="0" izz="0" />
		</inertial>
	</link>
	<joint name="wrist_center_joint" type="fixed">
		<origin xyz="-0.018 0.002853 0.001734" rpy="0 0 0" />
		<parent link="fih_z_hand_r_base_link" />
		<child link="wrist_center" />
	</joint>

	<link name="thumb_tip">
		<inertial>
			<origin xyz="0 0 0" rpy="0 0 0" />
			<mass value="0" />
			<inertia ixx="0" ixy="0" ixz="0" iyy="0" iyz="0" izz="0" />
		</inertial>
	</link>
	<joint name="thumb_tip_joint" type="fixed">
		<origin xyz="0.015 0 0" rpy="0 0 0" />
		<parent link="L_T_J4" />
		<child link="thumb_tip" />
	</joint>

	<link name="finger1_tip">
		<inertial>
			<origin xyz="0 0 0" rpy="0 0 0" />
			<mass value="0" />
			<inertia ixx="0" ixy="0" ixz="0" iyy="0" iyz="0" izz="0" />
		</inertial>
	</link>
	<joint name="finger1_tip_joint" type="fixed">
		<origin xyz="0.015 0 0" rpy="0 0 0" />
		<parent link="L_F1_J4" />
		<child link="finger1_tip" />
	</joint>

	<link name="finger2_tip">
		<inertial>
			<origin xyz="0 0 0" rpy="0 0 0" />
			<mass value="0" />
			<inertia ixx="0" ixy="0" ixz="0" iyy="0" iyz="0" izz="0" />
		</inertial>
	</link>
	<joint name="finger2_tip_joint" type="fixed">
		<origin xyz="0.015 0 0" rpy="0 0 0" />
		<parent link="L_F2_J4" />
		<child link="finger2_tip" />
	</joint>

	<link name="finger3_tip">
		<inertial>
			<origin xyz="0 0 0" rpy="0 0 0" />
			<mass value="0" />
			<inertia ixx="0" ixy="0" ixz="0" iyy="0" iyz="0" izz="0" />
		</inertial>
	</link>
	<joint name="finger3_tip_joint" type="fixed">
		<origin xyz="0.015 0 0" rpy="0 0 0" />
		<parent link="L_F3_J4" />
		<child link="finger3_tip" />
	</joint>

	<link name="finger4_tip">
		<inertial>
			<origin xyz="0 0 0" rpy="0 0 0" />
			<mass value="0" />
			<inertia ixx="0" ixy="0" ixz="0" iyy="0" iyz="0" izz="0" />
		</inertial>
	</link>
	<joint name="finger4_tip_joint" type="fixed">
		<origin xyz="0.015 0 0" rpy="0 0 0" />
		<parent link="L_F4_J4" />
		<child link="finger4_tip" />
	</joint>

</robot>